    condition = self.build_lookup(lookups, col, value)
  File "/home/mrpleasant/PycharmProjects/venv_django/lib/python3.5/site-packages/django/db/models/sql/query.py", line 1110, in build_lookup
    lhs = self.try_transform(lhs, lookup_name)
  File "/home/mrpleasant/PycharmProjects/venv_django/lib/python3.5/site-packages/django/db/models/sql/query.py", line 1151, in try_transform
    "permitted%s" % (name, output_field.__name__, suggestion)
django.core.exceptions.FieldError: Unsupported lookup 'startwith' for TextField or join on the field not permitted, perhaps you meant startswith or istartswith?
>>> Choice.objects.filter(text__startswith="P", text__endswith="l")
<QuerySet [<Choice: Praful>]>
>>> cls
Traceback (most recent call last):
  File "<console>", line 1, in <module>
NameError: name 'cls' is not defined
>>> 
[5]+  Stopped                 python manage.py shell
(venv_django) mrpleasant@ubuntu:~/PycharmProjects/Django/hardik_dj/employee management system$ cls
No command 'cls' found, but there are 18 similar ones
cls: command not found
(venv_django) mrpleasant@ubuntu:~/PycharmProjects/Django/hardik_dj/employee management system$ clear

(venv_django) mrpleasant@ubuntu:~/PycharmProjects/Django/hardik_dj/employee management system$ python manage.py makemigration
^[[1;5AUnknown command: 'makemigration'. Did you mean makemigrations?
Type 'manage.py help' for usage.
(venv_django) mrpleasant@ubuntu:~/PycharmProjects/Django/hardik_dj/employee management system$ python manage.py makemigrations
No changes detected
(venv_django) mrpleasant@ubuntu:~/PycharmProjects/Django/hardik_dj/employee management system$ python manage.py makemigrations
Migrations for 'employee':
  employee/migrations/0001_initial.py
    - Create model Profile
(venv_django) mrpleasant@ubuntu:~/PycharmProjects/Django/hardik_dj/employee management system$ python manage.py sqlmigrate
usage: manage.py sqlmigrate [-h] [--database DATABASE] [--backwards]
                            [--version] [-v {0,1,2,3}] [--settings SETTINGS]
                            [--pythonpath PYTHONPATH] [--traceback]
                            [--no-color] [--force-color]
                            app_label migration_name
manage.py sqlmigrate: error: the following arguments are required: app_label, migration_name
(venv_django) mrpleasant@ubuntu:~/PycharmProjects/Django/hardik_dj/employee management system$ python manage.py makemigrations
Migrations for 'poll':
  poll/migrations/0003_auto_20190726_0931.py
    - Alter field created_by on question
(venv_django) mrpleasant@ubuntu:~/PycharmProjects/Django/hardik_dj/employee management system$ python manage.py migrate
Operations to perform:
  Apply all migrations: admin, auth, contenttypes, employee, poll, sessions
Running migrations:
  Applying employee.0001_initial... OK
  Applying poll.0003_auto_20190726_0931... OK
(venv_django) mrpleasant@ubuntu:~/PycharmProjects/Django/hardik_dj/employee management system$ python manage.py runserver
Watching for file changes with StatReloader
Performing system checks...

System check identified no issues (0 silenced).
July 26, 2019 - 09:39:13
Django version 2.2.3, using settings 'ems.settings'
Starting development server at http://127.0.0.1:8000/
Quit the server with CONTROL-C.
[26/Jul/2019 09:39:53] "GET /admin/auth/ HTTP/1.1" 200 2968
[26/Jul/2019 09:39:58] "GET /admin/ HTTP/1.1" 200 4835
[26/Jul/2019 09:40:02] "GET /admin/ HTTP/1.1" 200 4835
[26/Jul/2019 09:40:27] "GET /admin/employee/profile/ HTTP/1.1" 200 3184
[26/Jul/2019 09:40:27] "GET /admin/jsi18n/ HTTP/1.1" 200 3223
[26/Jul/2019 09:40:27] "GET /static/admin/js/vendor/jquery/jquery.js HTTP/1.1" 200 271817
[26/Jul/2019 09:40:29] "GET /admin/employee/ HTTP/1.1" 200 2466
[26/Jul/2019 09:40:32] "GET /admin/ HTTP/1.1" 200 4835
[26/Jul/2019 09:40:34] "GET /admin/poll/choice/ HTTP/1.1" 200 4320
[26/Jul/2019 09:40:34] "GET /admin/jsi18n/ HTTP/1.1" 200 3223
[26/Jul/2019 09:40:48] "GET /admin/poll/ HTTP/1.1" 200 2853
[26/Jul/2019 09:40:49] "GET /admin/ HTTP/1.1" 200 4835
[26/Jul/2019 09:40:52] "GET /admin/poll/choice/ HTTP/1.1" 200 4320
[26/Jul/2019 09:40:52] "GET /admin/jsi18n/ HTTP/1.1" 200 3223
[26/Jul/2019 09:40:54] "GET /admin/poll/choice/1/change/ HTTP/1.1" 200 5596
[26/Jul/2019 09:40:54] "GET /admin/jsi18n/ HTTP/1.1" 200 3223
[26/Jul/2019 09:40:54] "GET /static/admin/img/icon-deletelink.svg HTTP/1.1" 200 392
[26/Jul/2019 09:40:59] "GET /admin/poll/choice/ HTTP/1.1" 200 4320
[26/Jul/2019 09:40:59] "GET /admin/jsi18n/ HTTP/1.1" 200 3223
[26/Jul/2019 09:41:01] "GET /admin/poll/ HTTP/1.1" 200 2853
[26/Jul/2019 09:41:05] "GET /admin/poll/question/ HTTP/1.1" 200 4352
[26/Jul/2019 09:41:05] "GET /admin/jsi18n/ HTTP/1.1" 200 3223
[26/Jul/2019 09:41:09] "GET /admin/poll/ HTTP/1.1" 200 2853
[26/Jul/2019 09:41:10] "GET /admin/ HTTP/1.1" 200 4835
[26/Jul/2019 09:41:14] "GET /admin/poll/question/ HTTP/1.1" 200 4352
[26/Jul/2019 09:41:14] "GET /admin/jsi18n/ HTTP/1.1" 200 3223
[26/Jul/2019 09:41:17] "GET /admin/ HTTP/1.1" 200 4835
[26/Jul/2019 09:41:51] "GET /admin/employee/profile/ HTTP/1.1" 200 3184
[26/Jul/2019 09:41:51] "GET /admin/jsi18n/ HTTP/1.1" 200 3223
[26/Jul/2019 09:41:53] "GET /admin/employee/profile/add/ HTTP/1.1" 200 5832
[26/Jul/2019 09:41:53] "GET /admin/jsi18n/ HTTP/1.1" 200 3223
[26/Jul/2019 09:43:25] "POST /admin/employee/profile/add/ HTTP/1.1" 302 0
[26/Jul/2019 09:43:25] "GET /admin/employee/profile/ HTTP/1.1" 200 4524
[26/Jul/2019 09:43:25] "GET /admin/jsi18n/ HTTP/1.1" 200 3223
/home/mrpleasant/PycharmProjects/Django/hardik_dj/employee management system/employee/models.py changed, reloading.
Watching for file changes with StatReloader
Performing system checks...

System check identified no issues (0 silenced).
July 26, 2019 - 09:44:13
Django version 2.2.3, using settings 'ems.settings'
Starting development server at http://127.0.0.1:8000/
Quit the server with CONTROL-C.
[26/Jul/2019 09:45:11] "GET /admin/employee/ HTTP/1.1" 200 2466
[26/Jul/2019 09:45:13] "GET /admin/ HTTP/1.1" 200 5151
[26/Jul/2019 09:45:24] "GET /admin/auth/user/ HTTP/1.1" 200 6609
[26/Jul/2019 09:45:24] "GET /admin/jsi18n/ HTTP/1.1" 200 3223
[26/Jul/2019 09:45:28] "GET /admin/auth/user/1/change/ HTTP/1.1" 200 14739
[26/Jul/2019 09:45:28] "GET /admin/jsi18n/ HTTP/1.1" 200 3223
[26/Jul/2019 09:45:53] "POST /admin/auth/user/1/change/ HTTP/1.1" 302 0
[26/Jul/2019 09:45:53] "GET /admin/auth/user/ HTTP/1.1" 200 6776
[26/Jul/2019 09:45:53] "GET /admin/jsi18n/ HTTP/1.1" 200 3223
[26/Jul/2019 09:46:21] "GET /admin/auth/ HTTP/1.1" 200 2966
[26/Jul/2019 09:46:24] "GET /admin/ HTTP/1.1" 200 5429
[26/Jul/2019 09:46:26] "GET /admin/employee/profile/ HTTP/1.1" 200 4349
[26/Jul/2019 09:46:26] "GET /admin/jsi18n/ HTTP/1.1" 200 3223
[26/Jul/2019 09:46:56] "GET /admin/employee/ HTTP/1.1" 200 2464
[26/Jul/2019 09:46:58] "GET /admin/employee/profile/ HTTP/1.1" 200 4349
[26/Jul/2019 09:46:58] "GET /admin/jsi18n/ HTTP/1.1" 200 3223
[26/Jul/2019 09:47:00] "GET /admin/employee/ HTTP/1.1" 200 2464
[26/Jul/2019 09:47:01] "GET /admin/employee/profile/add/ HTTP/1.1" 200 5830
[26/Jul/2019 09:47:02] "GET /admin/jsi18n/ HTTP/1.1" 200 3223
[26/Jul/2019 09:47:31] "POST /admin/employee/profile/add/ HTTP/1.1" 200 6030
[26/Jul/2019 09:47:31] "GET /admin/jsi18n/ HTTP/1.1" 200 3223
[26/Jul/2019 10:02:16] "POST /admin/employee/profile/add/ HTTP/1.1" 200 6030
[26/Jul/2019 10:02:16] "GET /admin/jsi18n/ HTTP/1.1" 200 3223
/home/mrpleasant/PycharmProjects/Django/hardik_dj/employee management system/employee/models.py changed, reloading.
Watching for file changes with StatReloader
Exception in thread django-main-thread:
Traceback (most recent call last):
  File "/usr/lib/python3.5/threading.py", line 914, in _bootstrap_inner
    self.run()
  File "/usr/lib/python3.5/threading.py", line 862, in run
    self._target(*self._args, **self._kwargs)
  File "/home/mrpleasant/PycharmProjects/venv_django/lib/python3.5/site-packages/django/utils/autoreload.py", line 54, in wrapper
    fn(*args, **kwargs)
  File "/home/mrpleasant/PycharmProjects/venv_django/lib/python3.5/site-packages/django/core/management/commands/runserver.py", line 109, in inner_run
    autoreload.raise_last_exception()
  File "/home/mrpleasant/PycharmProjects/venv_django/lib/python3.5/site-packages/django/utils/autoreload.py", line 77, in raise_last_exception
    raise _exception[1]
  File "/home/mrpleasant/PycharmProjects/venv_django/lib/python3.5/site-packages/django/core/management/__init__.py", line 337, in execute
    autoreload.check_errors(django.setup)()
  File "/home/mrpleasant/PycharmProjects/venv_django/lib/python3.5/site-packages/django/utils/autoreload.py", line 54, in wrapper
    fn(*args, **kwargs)
  File "/home/mrpleasant/PycharmProjects/venv_django/lib/python3.5/site-packages/django/__init__.py", line 24, in setup
    apps.populate(settings.INSTALLED_APPS)
  File "/home/mrpleasant/PycharmProjects/venv_django/lib/python3.5/site-packages/django/apps/registry.py", line 114, in populate
    app_config.import_models()
  File "/home/mrpleasant/PycharmProjects/venv_django/lib/python3.5/site-packages/django/apps/config.py", line 211, in import_models
    self.models_module = import_module(models_module_name)
  File "/home/mrpleasant/PycharmProjects/venv_django/lib/python3.5/importlib/__init__.py", line 126, in import_module
    return _bootstrap._gcd_import(name[level:], package, level)
  File "<frozen importlib._bootstrap>", line 986, in _gcd_import
  File "<frozen importlib._bootstrap>", line 969, in _find_and_load
  File "<frozen importlib._bootstrap>", line 958, in _find_and_load_unlocked
  File "<frozen importlib._bootstrap>", line 673, in _load_unlocked
  File "<frozen importlib._bootstrap_external>", line 669, in exec_module
  File "<frozen importlib._bootstrap_external>", line 775, in get_code
  File "<frozen importlib._bootstrap_external>", line 735, in source_to_code
  File "<frozen importlib._bootstrap>", line 222, in _call_with_frames_removed
  File "/home/mrpleasant/PycharmProjects/Django/hardik_dj/employee management system/employee/models.py", line 4
    from
        ^
SyntaxError: invalid syntax

/home/mrpleasant/PycharmProjects/Django/hardik_dj/employee management system/employee/models.py changed, reloading.
Watching for file changes with StatReloader
Exception in thread django-main-thread:
Traceback (most recent call last):
  File "/usr/lib/python3.5/threading.py", line 914, in _bootstrap_inner
    self.run()
  File "/usr/lib/python3.5/threading.py", line 862, in run
    self._target(*self._args, **self._kwargs)
  File "/home/mrpleasant/PycharmProjects/venv_django/lib/python3.5/site-packages/django/utils/autoreload.py", line 54, in wrapper
    fn(*args, **kwargs)
  File "/home/mrpleasant/PycharmProjects/venv_django/lib/python3.5/site-packages/django/core/management/commands/runserver.py", line 109, in inner_run
    autoreload.raise_last_exception()
  File "/home/mrpleasant/PycharmProjects/venv_django/lib/python3.5/site-packages/django/utils/autoreload.py", line 77, in raise_last_exception
    raise _exception[1]
  File "/home/mrpleasant/PycharmProjects/venv_django/lib/python3.5/site-packages/django/core/management/__init__.py", line 337, in execute
    autoreload.check_errors(django.setup)()
  File "/home/mrpleasant/PycharmProjects/venv_django/lib/python3.5/site-packages/django/utils/autoreload.py", line 54, in wrapper
    fn(*args, **kwargs)
  File "/home/mrpleasant/PycharmProjects/venv_django/lib/python3.5/site-packages/django/__init__.py", line 24, in setup
    apps.populate(settings.INSTALLED_APPS)
  File "/home/mrpleasant/PycharmProjects/venv_django/lib/python3.5/site-packages/django/apps/registry.py", line 114, in populate
    app_config.import_models()
  File "/home/mrpleasant/PycharmProjects/venv_django/lib/python3.5/site-packages/django/apps/config.py", line 211, in import_models
    self.models_module = import_module(models_module_name)
  File "/home/mrpleasant/PycharmProjects/venv_django/lib/python3.5/importlib/__init__.py", line 126, in import_module
    return _bootstrap._gcd_import(name[level:], package, level)
  File "<frozen importlib._bootstrap>", line 986, in _gcd_import
  File "<frozen importlib._bootstrap>", line 969, in _find_and_load
  File "<frozen importlib._bootstrap>", line 958, in _find_and_load_unlocked
  File "<frozen importlib._bootstrap>", line 673, in _load_unlocked
  File "<frozen importlib._bootstrap_external>", line 669, in exec_module
  File "<frozen importlib._bootstrap_external>", line 775, in get_code
  File "<frozen importlib._bootstrap_external>", line 735, in source_to_code
  File "<frozen importlib._bootstrap>", line 222, in _call_with_frames_removed
  File "/home/mrpleasant/PycharmProjects/Django/hardik_dj/employee management system/employee/models.py", line 4
    from django.dispatch import
                               ^
SyntaxError: invalid syntax

/home/mrpleasant/PycharmProjects/Django/hardik_dj/employee management system/employee/models.py changed, reloading.
Watching for file changes with StatReloader
Performing system checks...

System check identified no issues (0 silenced).
July 26, 2019 - 10:22:22
Django version 2.2.3, using settings 'ems.settings'
Starting development server at http://127.0.0.1:8000/
Quit the server with CONTROL-C.
/home/mrpleasant/PycharmProjects/Django/hardik_dj/employee management system/employee/models.py changed, reloading.
Watching for file changes with StatReloader
Exception in thread django-main-thread:
Traceback (most recent call last):
  File "/usr/lib/python3.5/threading.py", line 914, in _bootstrap_inner
    self.run()
  File "/usr/lib/python3.5/threading.py", line 862, in run
    self._target(*self._args, **self._kwargs)
  File "/home/mrpleasant/PycharmProjects/venv_django/lib/python3.5/site-packages/django/utils/autoreload.py", line 54, in wrapper
    fn(*args, **kwargs)
  File "/home/mrpleasant/PycharmProjects/venv_django/lib/python3.5/site-packages/django/core/management/commands/runserver.py", line 109, in inner_run
    autoreload.raise_last_exception()
  File "/home/mrpleasant/PycharmProjects/venv_django/lib/python3.5/site-packages/django/utils/autoreload.py", line 77, in raise_last_exception
    raise _exception[1]
  File "/home/mrpleasant/PycharmProjects/venv_django/lib/python3.5/site-packages/django/core/management/__init__.py", line 337, in execute
    autoreload.check_errors(django.setup)()
  File "/home/mrpleasant/PycharmProjects/venv_django/lib/python3.5/site-packages/django/utils/autoreload.py", line 54, in wrapper
    fn(*args, **kwargs)
  File "/home/mrpleasant/PycharmProjects/venv_django/lib/python3.5/site-packages/django/__init__.py", line 24, in setup
    apps.populate(settings.INSTALLED_APPS)
  File "/home/mrpleasant/PycharmProjects/venv_django/lib/python3.5/site-packages/django/apps/registry.py", line 114, in populate
    app_config.import_models()
  File "/home/mrpleasant/PycharmProjects/venv_django/lib/python3.5/site-packages/django/apps/config.py", line 211, in import_models
    self.models_module = import_module(models_module_name)
  File "/home/mrpleasant/PycharmProjects/venv_django/lib/python3.5/importlib/__init__.py", line 126, in import_module
    return _bootstrap._gcd_import(name[level:], package, level)
  File "<frozen importlib._bootstrap>", line 986, in _gcd_import
  File "<frozen importlib._bootstrap>", line 969, in _find_and_load
  File "<frozen importlib._bootstrap>", line 958, in _find_and_load_unlocked
  File "<frozen importlib._bootstrap>", line 673, in _load_unlocked
  File "<frozen importlib._bootstrap_external>", line 669, in exec_module
  File "<frozen importlib._bootstrap_external>", line 775, in get_code
  File "<frozen importlib._bootstrap_external>", line 735, in source_to_code
  File "<frozen importlib._bootstrap>", line 222, in _call_with_frames_removed
  File "/home/mrpleasant/PycharmProjects/Django/hardik_dj/employee management system/employee/models.py", line 20
    def user_c
             ^
SyntaxError: invalid syntax

/home/mrpleasant/PycharmProjects/Django/hardik_dj/employee management system/employee/models.py changed, reloading.
Watching for file changes with StatReloader
Exception in thread django-main-thread:
Traceback (most recent call last):
  File "/usr/lib/python3.5/threading.py", line 914, in _bootstrap_inner
    self.run()
  File "/usr/lib/python3.5/threading.py", line 862, in run
    self._target(*self._args, **self._kwargs)
  File "/home/mrpleasant/PycharmProjects/venv_django/lib/python3.5/site-packages/django/utils/autoreload.py", line 54, in wrapper
    fn(*args, **kwargs)
  File "/home/mrpleasant/PycharmProjects/venv_django/lib/python3.5/site-packages/django/core/management/commands/runserver.py", line 109, in inner_run
    autoreload.raise_last_exception()
  File "/home/mrpleasant/PycharmProjects/venv_django/lib/python3.5/site-packages/django/utils/autoreload.py", line 77, in raise_last_exception
    raise _exception[1]
  File "/home/mrpleasant/PycharmProjects/venv_django/lib/python3.5/site-packages/django/core/management/__init__.py", line 337, in execute
    autoreload.check_errors(django.setup)()
  File "/home/mrpleasant/PycharmProjects/venv_django/lib/python3.5/site-packages/django/utils/autoreload.py", line 54, in wrapper
    fn(*args, **kwargs)
  File "/home/mrpleasant/PycharmProjects/venv_django/lib/python3.5/site-packages/django/__init__.py", line 24, in setup
    apps.populate(settings.INSTALLED_APPS)
  File "/home/mrpleasant/PycharmProjects/venv_django/lib/python3.5/site-packages/django/apps/registry.py", line 114, in populate
    app_config.import_models()
  File "/home/mrpleasant/PycharmProjects/venv_django/lib/python3.5/site-packages/django/apps/config.py", line 211, in import_models
    self.models_module = import_module(models_module_name)
  File "/home/mrpleasant/PycharmProjects/venv_django/lib/python3.5/importlib/__init__.py", line 126, in import_module
    return _bootstrap._gcd_import(name[level:], package, level)
  File "<frozen importlib._bootstrap>", line 986, in _gcd_import
  File "<frozen importlib._bootstrap>", line 969, in _find_and_load
  File "<frozen importlib._bootstrap>", line 958, in _find_and_load_unlocked
  File "<frozen importlib._bootstrap>", line 673, in _load_unlocked
  File "<frozen importlib._bootstrap_external>", line 669, in exec_module
  File "<frozen importlib._bootstrap_external>", line 775, in get_code
  File "<frozen importlib._bootstrap_external>", line 735, in source_to_code
  File "<frozen importlib._bootstrap>", line 222, in _call_with_frames_removed
  File "/home/mrpleasant/PycharmProjects/Django/hardik_dj/employee management system/employee/models.py", line 20
    def user_is_created
                      ^
SyntaxError: invalid syntax

/home/mrpleasant/PycharmProjects/Django/hardik_dj/employee management system/employee/models.py changed, reloading.
Watching for file changes with StatReloader
Exception in thread django-main-thread:
Traceback (most recent call last):
  File "/usr/lib/python3.5/threading.py", line 914, in _bootstrap_inner
    self.run()
  File "/usr/lib/python3.5/threading.py", line 862, in run
    self._target(*self._args, **self._kwargs)
  File "/home/mrpleasant/PycharmProjects/venv_django/lib/python3.5/site-packages/django/utils/autoreload.py", line 54, in wrapper
    fn(*args, **kwargs)
  File "/home/mrpleasant/PycharmProjects/venv_django/lib/python3.5/site-packages/django/core/management/commands/runserver.py", line 109, in inner_run
    autoreload.raise_last_exception()
  File "/home/mrpleasant/PycharmProjects/venv_django/lib/python3.5/site-packages/django/utils/autoreload.py", line 77, in raise_last_exception
    raise _exception[1]
  File "/home/mrpleasant/PycharmProjects/venv_django/lib/python3.5/site-packages/django/core/management/__init__.py", line 337, in execute
    autoreload.check_errors(django.setup)()
  File "/home/mrpleasant/PycharmProjects/venv_django/lib/python3.5/site-packages/django/utils/autoreload.py", line 54, in wrapper
    fn(*args, **kwargs)
  File "/home/mrpleasant/PycharmProjects/venv_django/lib/python3.5/site-packages/django/__init__.py", line 24, in setup
    apps.populate(settings.INSTALLED_APPS)
  File "/home/mrpleasant/PycharmProjects/venv_django/lib/python3.5/site-packages/django/apps/registry.py", line 114, in populate
    app_config.import_models()
  File "/home/mrpleasant/PycharmProjects/venv_django/lib/python3.5/site-packages/django/apps/config.py", line 211, in import_models
    self.models_module = import_module(models_module_name)
  File "/home/mrpleasant/PycharmProjects/venv_django/lib/python3.5/importlib/__init__.py", line 126, in import_module
    return _bootstrap._gcd_import(name[level:], package, level)
  File "<frozen importlib._bootstrap>", line 986, in _gcd_import
  File "<frozen importlib._bootstrap>", line 969, in _find_and_load
  File "<frozen importlib._bootstrap>", line 958, in _find_and_load_unlocked
  File "<frozen importlib._bootstrap>", line 673, in _load_unlocked
  File "<frozen importlib._bootstrap_external>", line 669, in exec_module
  File "<frozen importlib._bootstrap_external>", line 775, in get_code
  File "<frozen importlib._bootstrap_external>", line 735, in source_to_code
  File "<frozen importlib._bootstrap>", line 222, in _call_with_frames_removed
  File "/home/mrpleasant/PycharmProjects/Django/hardik_dj/employee management system/employee/models.py", line 20
    def user_is_created(user,)
                             ^
SyntaxError: invalid syntax

/home/mrpleasant/PycharmProjects/Django/hardik_dj/employee management system/employee/models.py changed, reloading.
Watching for file changes with StatReloader
Exception in thread django-main-thread:
Traceback (most recent call last):
  File "/usr/lib/python3.5/threading.py", line 914, in _bootstrap_inner
    self.run()
  File "/usr/lib/python3.5/threading.py", line 862, in run
    self._target(*self._args, **self._kwargs)
  File "/home/mrpleasant/PycharmProjects/venv_django/lib/python3.5/site-packages/django/utils/autoreload.py", line 54, in wrapper
    fn(*args, **kwargs)
  File "/home/mrpleasant/PycharmProjects/venv_django/lib/python3.5/site-packages/django/core/management/commands/runserver.py", line 109, in inner_run
    autoreload.raise_last_exception()
  File "/home/mrpleasant/PycharmProjects/venv_django/lib/python3.5/site-packages/django/utils/autoreload.py", line 77, in raise_last_exception
    raise _exception[1]
  File "/home/mrpleasant/PycharmProjects/venv_django/lib/python3.5/site-packages/django/core/management/__init__.py", line 337, in execute
    autoreload.check_errors(django.setup)()
  File "/home/mrpleasant/PycharmProjects/venv_django/lib/python3.5/site-packages/django/utils/autoreload.py", line 54, in wrapper
    fn(*args, **kwargs)
  File "/home/mrpleasant/PycharmProjects/venv_django/lib/python3.5/site-packages/django/__init__.py", line 24, in setup
    apps.populate(settings.INSTALLED_APPS)
  File "/home/mrpleasant/PycharmProjects/venv_django/lib/python3.5/site-packages/django/apps/registry.py", line 114, in populate
    app_config.import_models()
  File "/home/mrpleasant/PycharmProjects/venv_django/lib/python3.5/site-packages/django/apps/config.py", line 211, in import_models
    self.models_module = import_module(models_module_name)
  File "/home/mrpleasant/PycharmProjects/venv_django/lib/python3.5/importlib/__init__.py", line 126, in import_module
    return _bootstrap._gcd_import(name[level:], package, level)
  File "<frozen importlib._bootstrap>", line 986, in _gcd_import
  File "<frozen importlib._bootstrap>", line 969, in _find_and_load
  File "<frozen importlib._bootstrap>", line 958, in _find_and_load_unlocked
  File "<frozen importlib._bootstrap>", line 673, in _load_unlocked
  File "<frozen importlib._bootstrap_external>", line 669, in exec_module
  File "<frozen importlib._bootstrap_external>", line 775, in get_code
  File "<frozen importlib._bootstrap_external>", line 735, in source_to_code
  File "<frozen importlib._bootstrap>", line 222, in _call_with_frames_removed
  File "/home/mrpleasant/PycharmProjects/Django/hardik_dj/employee management system/employee/models.py", line 20
    def user_is_created(sender,)
                               ^
SyntaxError: invalid syntax

/home/mrpleasant/PycharmProjects/Django/hardik_dj/employee management system/employee/models.py changed, reloading.
Watching for file changes with StatReloader
Exception in thread django-main-thread:
Traceback (most recent call last):
  File "/usr/lib/python3.5/threading.py", line 914, in _bootstrap_inner
    self.run()
  File "/usr/lib/python3.5/threading.py", line 862, in run
    self._target(*self._args, **self._kwargs)
  File "/home/mrpleasant/PycharmProjects/venv_django/lib/python3.5/site-packages/django/utils/autoreload.py", line 54, in wrapper
    fn(*args, **kwargs)
  File "/home/mrpleasant/PycharmProjects/venv_django/lib/python3.5/site-packages/django/core/management/commands/runserver.py", line 109, in inner_run
    autoreload.raise_last_exception()
  File "/home/mrpleasant/PycharmProjects/venv_django/lib/python3.5/site-packages/django/utils/autoreload.py", line 77, in raise_last_exception
    raise _exception[1]
  File "/home/mrpleasant/PycharmProjects/venv_django/lib/python3.5/site-packages/django/core/management/__init__.py", line 337, in execute
    autoreload.check_errors(django.setup)()
  File "/home/mrpleasant/PycharmProjects/venv_django/lib/python3.5/site-packages/django/utils/autoreload.py", line 54, in wrapper
    fn(*args, **kwargs)
  File "/home/mrpleasant/PycharmProjects/venv_django/lib/python3.5/site-packages/django/__init__.py", line 24, in setup
    apps.populate(settings.INSTALLED_APPS)
  File "/home/mrpleasant/PycharmProjects/venv_django/lib/python3.5/site-packages/django/apps/registry.py", line 114, in populate
    app_config.import_models()
  File "/home/mrpleasant/PycharmProjects/venv_django/lib/python3.5/site-packages/django/apps/config.py", line 211, in import_models
    self.models_module = import_module(models_module_name)
  File "/home/mrpleasant/PycharmProjects/venv_django/lib/python3.5/importlib/__init__.py", line 126, in import_module
    return _bootstrap._gcd_import(name[level:], package, level)
  File "<frozen importlib._bootstrap>", line 986, in _gcd_import
  File "<frozen importlib._bootstrap>", line 969, in _find_and_load
  File "<frozen importlib._bootstrap>", line 958, in _find_and_load_unlocked
  File "<frozen importlib._bootstrap>", line 673, in _load_unlocked
  File "<frozen importlib._bootstrap_external>", line 669, in exec_module
  File "<frozen importlib._bootstrap_external>", line 775, in get_code
  File "<frozen importlib._bootstrap_external>", line 735, in source_to_code
  File "<frozen importlib._bootstrap>", line 222, in _call_with_frames_removed
  File "/home/mrpleasant/PycharmProjects/Django/hardik_dj/employee management system/employee/models.py", line 20
    def user_is_created(sender, instance, )
                                          ^
SyntaxError: invalid syntax

/home/mrpleasant/PycharmProjects/Django/hardik_dj/employee management system/employee/models.py changed, reloading.
Watching for file changes with StatReloader
Exception in thread django-main-thread:
Traceback (most recent call last):
  File "/usr/lib/python3.5/threading.py", line 914, in _bootstrap_inner
    self.run()
  File "/usr/lib/python3.5/threading.py", line 862, in run
    self._target(*self._args, **self._kwargs)
  File "/home/mrpleasant/PycharmProjects/venv_django/lib/python3.5/site-packages/django/utils/autoreload.py", line 54, in wrapper
    fn(*args, **kwargs)
  File "/home/mrpleasant/PycharmProjects/venv_django/lib/python3.5/site-packages/django/core/management/commands/runserver.py", line 109, in inner_run
    autoreload.raise_last_exception()
  File "/home/mrpleasant/PycharmProjects/venv_django/lib/python3.5/site-packages/django/utils/autoreload.py", line 77, in raise_last_exception
    raise _exception[1]
  File "/home/mrpleasant/PycharmProjects/venv_django/lib/python3.5/site-packages/django/core/management/__init__.py", line 337, in execute
    autoreload.check_errors(django.setup)()
  File "/home/mrpleasant/PycharmProjects/venv_django/lib/python3.5/site-packages/django/utils/autoreload.py", line 54, in wrapper
    fn(*args, **kwargs)
  File "/home/mrpleasant/PycharmProjects/venv_django/lib/python3.5/site-packages/django/__init__.py", line 24, in setup
    apps.populate(settings.INSTALLED_APPS)
  File "/home/mrpleasant/PycharmProjects/venv_django/lib/python3.5/site-packages/django/apps/registry.py", line 114, in populate
    app_config.import_models()
  File "/home/mrpleasant/PycharmProjects/venv_django/lib/python3.5/site-packages/django/apps/config.py", line 211, in import_models
    self.models_module = import_module(models_module_name)
  File "/home/mrpleasant/PycharmProjects/venv_django/lib/python3.5/importlib/__init__.py", line 126, in import_module
    return _bootstrap._gcd_import(name[level:], package, level)
  File "<frozen importlib._bootstrap>", line 986, in _gcd_import
  File "<frozen importlib._bootstrap>", line 969, in _find_and_load
  File "<frozen importlib._bootstrap>", line 958, in _find_and_load_unlocked
  File "<frozen importlib._bootstrap>", line 673, in _load_unlocked
  File "<frozen importlib._bootstrap_external>", line 669, in exec_module
  File "<frozen importlib._bootstrap_external>", line 775, in get_code
  File "<frozen importlib._bootstrap_external>", line 735, in source_to_code
  File "<frozen importlib._bootstrap>", line 222, in _call_with_frames_removed
  File "/home/mrpleasant/PycharmProjects/Django/hardik_dj/employee management system/employee/models.py", line 20
    def user_is_created(sender, instance, created, )
                                                   ^
SyntaxError: invalid syntax

/home/mrpleasant/PycharmProjects/Django/hardik_dj/employee management system/employee/models.py changed, reloading.
Watching for file changes with StatReloader
Exception in thread django-main-thread:
Traceback (most recent call last):
  File "/usr/lib/python3.5/threading.py", line 914, in _bootstrap_inner
    self.run()
  File "/usr/lib/python3.5/threading.py", line 862, in run
    self._target(*self._args, **self._kwargs)
  File "/home/mrpleasant/PycharmProjects/venv_django/lib/python3.5/site-packages/django/utils/autoreload.py", line 54, in wrapper
    fn(*args, **kwargs)
  File "/home/mrpleasant/PycharmProjects/venv_django/lib/python3.5/site-packages/django/core/management/commands/runserver.py", line 109, in inner_run
    autoreload.raise_last_exception()
  File "/home/mrpleasant/PycharmProjects/venv_django/lib/python3.5/site-packages/django/utils/autoreload.py", line 77, in raise_last_exception
    raise _exception[1]
  File "/home/mrpleasant/PycharmProjects/venv_django/lib/python3.5/site-packages/django/core/management/__init__.py", line 337, in execute
    autoreload.check_errors(django.setup)()
  File "/home/mrpleasant/PycharmProjects/venv_django/lib/python3.5/site-packages/django/utils/autoreload.py", line 54, in wrapper
    fn(*args, **kwargs)
  File "/home/mrpleasant/PycharmProjects/venv_django/lib/python3.5/site-packages/django/__init__.py", line 24, in setup
    apps.populate(settings.INSTALLED_APPS)
  File "/home/mrpleasant/PycharmProjects/venv_django/lib/python3.5/site-packages/django/apps/registry.py", line 114, in populate
    app_config.import_models()
  File "/home/mrpleasant/PycharmProjects/venv_django/lib/python3.5/site-packages/django/apps/config.py", line 211, in import_models
    self.models_module = import_module(models_module_name)
  File "/home/mrpleasant/PycharmProjects/venv_django/lib/python3.5/importlib/__init__.py", line 126, in import_module
    return _bootstrap._gcd_import(name[level:], package, level)
  File "<frozen importlib._bootstrap>", line 986, in _gcd_import
  File "<frozen importlib._bootstrap>", line 969, in _find_and_load
  File "<frozen importlib._bootstrap>", line 958, in _find_and_load_unlocked
  File "<frozen importlib._bootstrap>", line 673, in _load_unlocked
  File "<frozen importlib._bootstrap_external>", line 669, in exec_module
  File "<frozen importlib._bootstrap_external>", line 775, in get_code
  File "<frozen importlib._bootstrap_external>", line 735, in source_to_code
  File "<frozen importlib._bootstrap>", line 222, in _call_with_frames_removed
  File "/home/mrpleasant/PycharmProjects/Django/hardik_dj/employee management system/employee/models.py", line 20
    def user_is_created(sender, instance, created, **karg)
                                                         ^
SyntaxError: invalid syntax

/home/mrpleasant/PycharmProjects/Django/hardik_dj/employee management system/employee/models.py changed, reloading.
Watching for file changes with StatReloader
Exception in thread django-main-thread:
Traceback (most recent call last):
  File "/usr/lib/python3.5/threading.py", line 914, in _bootstrap_inner
    self.run()
  File "/usr/lib/python3.5/threading.py", line 862, in run
    self._target(*self._args, **self._kwargs)
  File "/home/mrpleasant/PycharmProjects/venv_django/lib/python3.5/site-packages/django/utils/autoreload.py", line 54, in wrapper
    fn(*args, **kwargs)
  File "/home/mrpleasant/PycharmProjects/venv_django/lib/python3.5/site-packages/django/core/management/commands/runserver.py", line 109, in inner_run
    autoreload.raise_last_exception()
  File "/home/mrpleasant/PycharmProjects/venv_django/lib/python3.5/site-packages/django/utils/autoreload.py", line 77, in raise_last_exception
    raise _exception[1]
  File "/home/mrpleasant/PycharmProjects/venv_django/lib/python3.5/site-packages/django/core/management/__init__.py", line 337, in execute
    autoreload.check_errors(django.setup)()
  File "/home/mrpleasant/PycharmProjects/venv_django/lib/python3.5/site-packages/django/utils/autoreload.py", line 54, in wrapper
    fn(*args, **kwargs)
  File "/home/mrpleasant/PycharmProjects/venv_django/lib/python3.5/site-packages/django/__init__.py", line 24, in setup
    apps.populate(settings.INSTALLED_APPS)
  File "/home/mrpleasant/PycharmProjects/venv_django/lib/python3.5/site-packages/django/apps/registry.py", line 114, in populate
    app_config.import_models()
  File "/home/mrpleasant/PycharmProjects/venv_django/lib/python3.5/site-packages/django/apps/config.py", line 211, in import_models
    self.models_module = import_module(models_module_name)
  File "/home/mrpleasant/PycharmProjects/venv_django/lib/python3.5/importlib/__init__.py", line 126, in import_module
    return _bootstrap._gcd_import(name[level:], package, level)
  File "<frozen importlib._bootstrap>", line 986, in _gcd_import
  File "<frozen importlib._bootstrap>", line 969, in _find_and_load
  File "<frozen importlib._bootstrap>", line 958, in _find_and_load_unlocked
  File "<frozen importlib._bootstrap>", line 673, in _load_unlocked
  File "<frozen importlib._bootstrap_external>", line 669, in exec_module
  File "<frozen importlib._bootstrap_external>", line 775, in get_code
  File "<frozen importlib._bootstrap_external>", line 735, in source_to_code
  File "<frozen importlib._bootstrap>", line 222, in _call_with_frames_removed
  File "/home/mrpleasant/PycharmProjects/Django/hardik_dj/employee management system/employee/models.py", line 21
    
    ^
SyntaxError: unexpected EOF while parsing

/home/mrpleasant/PycharmProjects/Django/hardik_dj/employee management system/employee/models.py changed, reloading.
Watching for file changes with StatReloader
Exception in thread django-main-thread:
Traceback (most recent call last):
  File "/usr/lib/python3.5/threading.py", line 914, in _bootstrap_inner
    self.run()
  File "/usr/lib/python3.5/threading.py", line 862, in run
    self._target(*self._args, **self._kwargs)
  File "/home/mrpleasant/PycharmProjects/venv_django/lib/python3.5/site-packages/django/utils/autoreload.py", line 54, in wrapper
    fn(*args, **kwargs)
  File "/home/mrpleasant/PycharmProjects/venv_django/lib/python3.5/site-packages/django/core/management/commands/runserver.py", line 109, in inner_run
    autoreload.raise_last_exception()
  File "/home/mrpleasant/PycharmProjects/venv_django/lib/python3.5/site-packages/django/utils/autoreload.py", line 77, in raise_last_exception
    raise _exception[1]
  File "/home/mrpleasant/PycharmProjects/venv_django/lib/python3.5/site-packages/django/core/management/__init__.py", line 337, in execute
    autoreload.check_errors(django.setup)()
  File "/home/mrpleasant/PycharmProjects/venv_django/lib/python3.5/site-packages/django/utils/autoreload.py", line 54, in wrapper
    fn(*args, **kwargs)
  File "/home/mrpleasant/PycharmProjects/venv_django/lib/python3.5/site-packages/django/__init__.py", line 24, in setup
    apps.populate(settings.INSTALLED_APPS)
  File "/home/mrpleasant/PycharmProjects/venv_django/lib/python3.5/site-packages/django/apps/registry.py", line 114, in populate
    app_config.import_models()
  File "/home/mrpleasant/PycharmProjects/venv_django/lib/python3.5/site-packages/django/apps/config.py", line 211, in import_models
    self.models_module = import_module(models_module_name)
  File "/home/mrpleasant/PycharmProjects/venv_django/lib/python3.5/importlib/__init__.py", line 126, in import_module
    return _bootstrap._gcd_import(name[level:], package, level)
  File "<frozen importlib._bootstrap>", line 986, in _gcd_import
  File "<frozen importlib._bootstrap>", line 969, in _find_and_load
  File "<frozen importlib._bootstrap>", line 958, in _find_and_load_unlocked
  File "<frozen importlib._bootstrap>", line 673, in _load_unlocked
  File "<frozen importlib._bootstrap_external>", line 669, in exec_module
  File "<frozen importlib._bootstrap_external>", line 775, in get_code
  File "<frozen importlib._bootstrap_external>", line 735, in source_to_code
  File "<frozen importlib._bootstrap>", line 222, in _call_with_frames_removed
  File "/home/mrpleasant/PycharmProjects/Django/hardik_dj/employee management system/employee/models.py", line 21
    @receiver(post_save, User=)
                              ^
SyntaxError: invalid syntax

/home/mrpleasant/PycharmProjects/Django/hardik_dj/employee management system/employee/models.py changed, reloading.
Watching for file changes with StatReloader
Exception in thread django-main-thread:
Traceback (most recent call last):
  File "/usr/lib/python3.5/threading.py", line 914, in _bootstrap_inner
    self.run()
  File "/usr/lib/python3.5/threading.py", line 862, in run
    self._target(*self._args, **self._kwargs)
  File "/home/mrpleasant/PycharmProjects/venv_django/lib/python3.5/site-packages/django/utils/autoreload.py", line 54, in wrapper
    fn(*args, **kwargs)
  File "/home/mrpleasant/PycharmProjects/venv_django/lib/python3.5/site-packages/django/core/management/commands/runserver.py", line 109, in inner_run
    autoreload.raise_last_exception()
  File "/home/mrpleasant/PycharmProjects/venv_django/lib/python3.5/site-packages/django/utils/autoreload.py", line 77, in raise_last_exception
    raise _exception[1]
  File "/home/mrpleasant/PycharmProjects/venv_django/lib/python3.5/site-packages/django/core/management/__init__.py", line 337, in execute
    autoreload.check_errors(django.setup)()
  File "/home/mrpleasant/PycharmProjects/venv_django/lib/python3.5/site-packages/django/utils/autoreload.py", line 54, in wrapper
    fn(*args, **kwargs)
  File "/home/mrpleasant/PycharmProjects/venv_django/lib/python3.5/site-packages/django/__init__.py", line 24, in setup
    apps.populate(settings.INSTALLED_APPS)
  File "/home/mrpleasant/PycharmProjects/venv_django/lib/python3.5/site-packages/django/apps/registry.py", line 114, in populate
    app_config.import_models()
  File "/home/mrpleasant/PycharmProjects/venv_django/lib/python3.5/site-packages/django/apps/config.py", line 211, in import_models
    self.models_module = import_module(models_module_name)
  File "/home/mrpleasant/PycharmProjects/venv_django/lib/python3.5/importlib/__init__.py", line 126, in import_module
    return _bootstrap._gcd_import(name[level:], package, level)
  File "<frozen importlib._bootstrap>", line 986, in _gcd_import
  File "<frozen importlib._bootstrap>", line 969, in _find_and_load
  File "<frozen importlib._bootstrap>", line 958, in _find_and_load_unlocked
  File "<frozen importlib._bootstrap>", line 673, in _load_unlocked
  File "<frozen importlib._bootstrap_external>", line 669, in exec_module
  File "<frozen importlib._bootstrap_external>", line 775, in get_code
  File "<frozen importlib._bootstrap_external>", line 735, in source_to_code
  File "<frozen importlib._bootstrap>", line 222, in _call_with_frames_removed
  File "/home/mrpleasant/PycharmProjects/Django/hardik_dj/employee management system/employee/models.py", line 23
    
    ^
SyntaxError: unexpected EOF while parsing

/home/mrpleasant/PycharmProjects/Django/hardik_dj/employee management system/employee/models.py changed, reloading.
Watching for file changes with StatReloader
Exception in thread django-main-thread:
Traceback (most recent call last):
  File "/usr/lib/python3.5/threading.py", line 914, in _bootstrap_inner
    self.run()
  File "/usr/lib/python3.5/threading.py", line 862, in run
    self._target(*self._args, **self._kwargs)
  File "/home/mrpleasant/PycharmProjects/venv_django/lib/python3.5/site-packages/django/utils/autoreload.py", line 54, in wrapper
    fn(*args, **kwargs)
  File "/home/mrpleasant/PycharmProjects/venv_django/lib/python3.5/site-packages/django/core/management/commands/runserver.py", line 109, in inner_run
    autoreload.raise_last_exception()
  File "/home/mrpleasant/PycharmProjects/venv_django/lib/python3.5/site-packages/django/utils/autoreload.py", line 77, in raise_last_exception
    raise _exception[1]
  File "/home/mrpleasant/PycharmProjects/venv_django/lib/python3.5/site-packages/django/core/management/__init__.py", line 337, in execute
    autoreload.check_errors(django.setup)()
  File "/home/mrpleasant/PycharmProjects/venv_django/lib/python3.5/site-packages/django/utils/autoreload.py", line 54, in wrapper
    fn(*args, **kwargs)
  File "/home/mrpleasant/PycharmProjects/venv_django/lib/python3.5/site-packages/django/__init__.py", line 24, in setup
    apps.populate(settings.INSTALLED_APPS)
  File "/home/mrpleasant/PycharmProjects/venv_django/lib/python3.5/site-packages/django/apps/registry.py", line 114, in populate
    app_config.import_models()
  File "/home/mrpleasant/PycharmProjects/venv_django/lib/python3.5/site-packages/django/apps/config.py", line 211, in import_models
    self.models_module = import_module(models_module_name)
  File "/home/mrpleasant/PycharmProjects/venv_django/lib/python3.5/importlib/__init__.py", line 126, in import_module
    return _bootstrap._gcd_import(name[level:], package, level)
  File "<frozen importlib._bootstrap>", line 986, in _gcd_import
  File "<frozen importlib._bootstrap>", line 969, in _find_and_load
  File "<frozen importlib._bootstrap>", line 958, in _find_and_load_unlocked
  File "<frozen importlib._bootstrap>", line 673, in _load_unlocked
  File "<frozen importlib._bootstrap_external>", line 669, in exec_module
  File "<frozen importlib._bootstrap_external>", line 775, in get_code
  File "<frozen importlib._bootstrap_external>", line 735, in source_to_code
  File "<frozen importlib._bootstrap>", line 222, in _call_with_frames_removed
  File "/home/mrpleasant/PycharmProjects/Django/hardik_dj/employee management system/employee/models.py", line 23
    if
     ^
SyntaxError: invalid syntax

/home/mrpleasant/PycharmProjects/Django/hardik_dj/employee management system/employee/models.py changed, reloading.
Watching for file changes with StatReloader
Exception in thread django-main-thread:
Traceback (most recent call last):
  File "/usr/lib/python3.5/threading.py", line 914, in _bootstrap_inner
    self.run()
  File "/usr/lib/python3.5/threading.py", line 862, in run
    self._target(*self._args, **self._kwargs)
  File "/home/mrpleasant/PycharmProjects/venv_django/lib/python3.5/site-packages/django/utils/autoreload.py", line 54, in wrapper
    fn(*args, **kwargs)
  File "/home/mrpleasant/PycharmProjects/venv_django/lib/python3.5/site-packages/django/core/management/commands/runserver.py", line 109, in inner_run
    autoreload.raise_last_exception()
  File "/home/mrpleasant/PycharmProjects/venv_django/lib/python3.5/site-packages/django/utils/autoreload.py", line 77, in raise_last_exception
    raise _exception[1]
  File "/home/mrpleasant/PycharmProjects/venv_django/lib/python3.5/site-packages/django/core/management/__init__.py", line 337, in execute
    autoreload.check_errors(django.setup)()
  File "/home/mrpleasant/PycharmProjects/venv_django/lib/python3.5/site-packages/django/utils/autoreload.py", line 54, in wrapper
    fn(*args, **kwargs)
  File "/home/mrpleasant/PycharmProjects/venv_django/lib/python3.5/site-packages/django/__init__.py", line 24, in setup
    apps.populate(settings.INSTALLED_APPS)
  File "/home/mrpleasant/PycharmProjects/venv_django/lib/python3.5/site-packages/django/apps/registry.py", line 114, in populate
    app_config.import_models()
  File "/home/mrpleasant/PycharmProjects/venv_django/lib/python3.5/site-packages/django/apps/config.py", line 211, in import_models
    self.models_module = import_module(models_module_name)
  File "/home/mrpleasant/PycharmProjects/venv_django/lib/python3.5/importlib/__init__.py", line 126, in import_module
    return _bootstrap._gcd_import(name[level:], package, level)
  File "<frozen importlib._bootstrap>", line 986, in _gcd_import
  File "<frozen importlib._bootstrap>", line 969, in _find_and_load
  File "<frozen importlib._bootstrap>", line 958, in _find_and_load_unlocked
  File "<frozen importlib._bootstrap>", line 673, in _load_unlocked
  File "<frozen importlib._bootstrap_external>", line 669, in exec_module
  File "<frozen importlib._bootstrap_external>", line 775, in get_code
  File "<frozen importlib._bootstrap_external>", line 735, in source_to_code
  File "<frozen importlib._bootstrap>", line 222, in _call_with_frames_removed
  File "/home/mrpleasant/PycharmProjects/Django/hardik_dj/employee management system/employee/models.py", line 25
    
    ^
SyntaxError: unexpected EOF while parsing

/home/mrpleasant/PycharmProjects/Django/hardik_dj/employee management system/employee/models.py changed, reloading.
Watching for file changes with StatReloader
Performing system checks...

System check identified no issues (0 silenced).
July 26, 2019 - 10:27:01
Django version 2.2.3, using settings 'ems.settings'
Starting development server at http://127.0.0.1:8000/
Quit the server with CONTROL-C.
/home/mrpleasant/PycharmProjects/Django/hardik_dj/employee management system/employee/models.py changed, reloading.
Watching for file changes with StatReloader
Performing system checks...

System check identified no issues (0 silenced).
July 26, 2019 - 10:27:13
Django version 2.2.3, using settings 'ems.settings'
Starting development server at http://127.0.0.1:8000/
Quit the server with CONTROL-C.
/home/mrpleasant/PycharmProjects/Django/hardik_dj/employee management system/employee/models.py changed, reloading.
Watching for file changes with StatReloader
Exception in thread django-main-thread:
Traceback (most recent call last):
  File "/usr/lib/python3.5/threading.py", line 914, in _bootstrap_inner
    self.run()
  File "/usr/lib/python3.5/threading.py", line 862, in run
    self._target(*self._args, **self._kwargs)
  File "/home/mrpleasant/PycharmProjects/venv_django/lib/python3.5/site-packages/django/utils/autoreload.py", line 54, in wrapper
    fn(*args, **kwargs)
  File "/home/mrpleasant/PycharmProjects/venv_django/lib/python3.5/site-packages/django/core/management/commands/runserver.py", line 109, in inner_run
    autoreload.raise_last_exception()
  File "/home/mrpleasant/PycharmProjects/venv_django/lib/python3.5/site-packages/django/utils/autoreload.py", line 77, in raise_last_exception
    raise _exception[1]
  File "/home/mrpleasant/PycharmProjects/venv_django/lib/python3.5/site-packages/django/core/management/__init__.py", line 337, in execute
    autoreload.check_errors(django.setup)()
  File "/home/mrpleasant/PycharmProjects/venv_django/lib/python3.5/site-packages/django/utils/autoreload.py", line 54, in wrapper
    fn(*args, **kwargs)
  File "/home/mrpleasant/PycharmProjects/venv_django/lib/python3.5/site-packages/django/__init__.py", line 24, in setup
    apps.populate(settings.INSTALLED_APPS)
  File "/home/mrpleasant/PycharmProjects/venv_django/lib/python3.5/site-packages/django/apps/registry.py", line 114, in populate
    app_config.import_models()
  File "/home/mrpleasant/PycharmProjects/venv_django/lib/python3.5/site-packages/django/apps/config.py", line 211, in import_models
    self.models_module = import_module(models_module_name)
  File "/home/mrpleasant/PycharmProjects/venv_django/lib/python3.5/importlib/__init__.py", line 126, in import_module
    return _bootstrap._gcd_import(name[level:], package, level)
  File "<frozen importlib._bootstrap>", line 986, in _gcd_import
  File "<frozen importlib._bootstrap>", line 969, in _find_and_load
  File "<frozen importlib._bootstrap>", line 958, in _find_and_load_unlocked
  File "<frozen importlib._bootstrap>", line 673, in _load_unlocked
  File "<frozen importlib._bootstrap_external>", line 669, in exec_module
  File "<frozen importlib._bootstrap_external>", line 775, in get_code
  File "<frozen importlib._bootstrap_external>", line 735, in source_to_code
  File "<frozen importlib._bootstrap>", line 222, in _call_with_frames_removed
  File "/home/mrpleasant/PycharmProjects/Django/hardik_dj/employee management system/employee/models.py", line 24
    profile =
             ^
SyntaxError: invalid syntax

/home/mrpleasant/PycharmProjects/Django/hardik_dj/employee management system/employee/models.py changed, reloading.
Watching for file changes with StatReloader
Exception in thread django-main-thread:
Traceback (most recent call last):
  File "/usr/lib/python3.5/threading.py", line 914, in _bootstrap_inner
    self.run()
  File "/usr/lib/python3.5/threading.py", line 862, in run
    self._target(*self._args, **self._kwargs)
  File "/home/mrpleasant/PycharmProjects/venv_django/lib/python3.5/site-packages/django/utils/autoreload.py", line 54, in wrapper
    fn(*args, **kwargs)
  File "/home/mrpleasant/PycharmProjects/venv_django/lib/python3.5/site-packages/django/core/management/commands/runserver.py", line 109, in inner_run
    autoreload.raise_last_exception()
  File "/home/mrpleasant/PycharmProjects/venv_django/lib/python3.5/site-packages/django/utils/autoreload.py", line 77, in raise_last_exception
    raise _exception[1]
  File "/home/mrpleasant/PycharmProjects/venv_django/lib/python3.5/site-packages/django/core/management/__init__.py", line 337, in execute
    autoreload.check_errors(django.setup)()
  File "/home/mrpleasant/PycharmProjects/venv_django/lib/python3.5/site-packages/django/utils/autoreload.py", line 54, in wrapper
    fn(*args, **kwargs)
  File "/home/mrpleasant/PycharmProjects/venv_django/lib/python3.5/site-packages/django/__init__.py", line 24, in setup
    apps.populate(settings.INSTALLED_APPS)
  File "/home/mrpleasant/PycharmProjects/venv_django/lib/python3.5/site-packages/django/apps/registry.py", line 114, in populate
    app_config.import_models()
  File "/home/mrpleasant/PycharmProjects/venv_django/lib/python3.5/site-packages/django/apps/config.py", line 211, in import_models
    self.models_module = import_module(models_module_name)
  File "/home/mrpleasant/PycharmProjects/venv_django/lib/python3.5/importlib/__init__.py", line 126, in import_module
    return _bootstrap._gcd_import(name[level:], package, level)
  File "<frozen importlib._bootstrap>", line 986, in _gcd_import
  File "<frozen importlib._bootstrap>", line 969, in _find_and_load
  File "<frozen importlib._bootstrap>", line 958, in _find_and_load_unlocked
  File "<frozen importlib._bootstrap>", line 673, in _load_unlocked
  File "<frozen importlib._bootstrap_external>", line 669, in exec_module
  File "<frozen importlib._bootstrap_external>", line 775, in get_code
  File "<frozen importlib._bootstrap_external>", line 735, in source_to_code
  File "<frozen importlib._bootstrap>", line 222, in _call_with_frames_removed
  File "/home/mrpleasant/PycharmProjects/Django/hardik_dj/employee management system/employee/models.py", line 24
    Profile.objects.
                   ^
SyntaxError: invalid syntax

/home/mrpleasant/PycharmProjects/Django/hardik_dj/employee management system/employee/models.py changed, reloading.
Watching for file changes with StatReloader
Performing system checks...

System check identified no issues (0 silenced).
July 26, 2019 - 10:29:25
Django version 2.2.3, using settings 'ems.settings'
Starting development server at http://127.0.0.1:8000/
Quit the server with CONTROL-C.
/home/mrpleasant/PycharmProjects/Django/hardik_dj/employee management system/employee/models.py changed, reloading.
Watching for file changes with StatReloader
Performing system checks...

System check identified no issues (0 silenced).
July 26, 2019 - 10:29:37
Django version 2.2.3, using settings 'ems.settings'
Starting development server at http://127.0.0.1:8000/
Quit the server with CONTROL-C.
/home/mrpleasant/PycharmProjects/Django/hardik_dj/employee management system/employee/models.py changed, reloading.
Watching for file changes with StatReloader
Exception in thread django-main-thread:
Traceback (most recent call last):
  File "/usr/lib/python3.5/threading.py", line 914, in _bootstrap_inner
    self.run()
  File "/usr/lib/python3.5/threading.py", line 862, in run
    self._target(*self._args, **self._kwargs)
  File "/home/mrpleasant/PycharmProjects/venv_django/lib/python3.5/site-packages/django/utils/autoreload.py", line 54, in wrapper
    fn(*args, **kwargs)
  File "/home/mrpleasant/PycharmProjects/venv_django/lib/python3.5/site-packages/django/core/management/commands/runserver.py", line 109, in inner_run
    autoreload.raise_last_exception()
  File "/home/mrpleasant/PycharmProjects/venv_django/lib/python3.5/site-packages/django/utils/autoreload.py", line 77, in raise_last_exception
    raise _exception[1]
  File "/home/mrpleasant/PycharmProjects/venv_django/lib/python3.5/site-packages/django/core/management/__init__.py", line 337, in execute
    autoreload.check_errors(django.setup)()
  File "/home/mrpleasant/PycharmProjects/venv_django/lib/python3.5/site-packages/django/utils/autoreload.py", line 54, in wrapper
    fn(*args, **kwargs)
  File "/home/mrpleasant/PycharmProjects/venv_django/lib/python3.5/site-packages/django/__init__.py", line 24, in setup
    apps.populate(settings.INSTALLED_APPS)
  File "/home/mrpleasant/PycharmProjects/venv_django/lib/python3.5/site-packages/django/apps/registry.py", line 114, in populate
    app_config.import_models()
  File "/home/mrpleasant/PycharmProjects/venv_django/lib/python3.5/site-packages/django/apps/config.py", line 211, in import_models
    self.models_module = import_module(models_module_name)
  File "/home/mrpleasant/PycharmProjects/venv_django/lib/python3.5/importlib/__init__.py", line 126, in import_module
    return _bootstrap._gcd_import(name[level:], package, level)
  File "<frozen importlib._bootstrap>", line 986, in _gcd_import
  File "<frozen importlib._bootstrap>", line 969, in _find_and_load
  File "<frozen importlib._bootstrap>", line 958, in _find_and_load_unlocked
  File "<frozen importlib._bootstrap>", line 673, in _load_unlocked
  File "<frozen importlib._bootstrap_external>", line 669, in exec_module
  File "<frozen importlib._bootstrap_external>", line 775, in get_code
  File "<frozen importlib._bootstrap_external>", line 735, in source_to_code
  File "<frozen importlib._bootstrap>", line 222, in _call_with_frames_removed
  File "/home/mrpleasant/PycharmProjects/Django/hardik_dj/employee management system/employee/models.py", line 29
    
    ^
SyntaxError: unexpected EOF while parsing

/home/mrpleasant/PycharmProjects/Django/hardik_dj/employee management system/employee/models.py changed, reloading.
Watching for file changes with StatReloader
Performing system checks...

System check identified no issues (0 silenced).
July 26, 2019 - 10:30:17
Django version 2.2.3, using settings 'ems.settings'
Starting development server at http://127.0.0.1:8000/
Quit the server with CONTROL-C.
^Z
[6]+  Stopped                 python manage.py runserver
(venv_django) mrpleasant@ubuntu:~/PycharmProjects/Django/hardik_dj/employee management system$ python manage.py shell
Python 3.5.3 (default, Nov 23 2017, 11:34:05) 
[GCC 6.3.0 20170406] on linux
Type "help", "copyright", "credits" or "license" for more information.
(InteractiveConsole)
>>> from django.contrib.auth.models import User
>>> from employee.models import Profile
>>> u = User()
>>> u.save()
>>> u.id
2
>>> Profile.objects.all()
<QuerySet [<Profile: pra tek>, <Profile:  >]>
>>> Profile.objects.get(user=2)
<Profile:  >
>>> Profile.objects.get(user=2).user.first_name
''
>>> Profile.objects.get(user=2).user.last_name
''
>>> Profile.objects.get(user=2).user.username
''
>>> u.first_name=shiv
Traceback (most recent call last):
  File "<console>", line 1, in <module>
NameError: name 'shiv' is not defined
>>> u.first_name='shiv'
>>> u.save()
>>> Profile.objects.get(user=2).user.username
''
>>> Profile.objects.get(user=2).user.last_name
''
>>> Profile.objects.get(user=2).user.first_name
'shiv'
>>> u.last_name='shiv'
>>> u.last_name='shiv_*'
>>> u.save()
>>> Profile.objects.get(user=2).user.last_name
'shiv_*'
>>> Profile.objects.get(user=2).user.designation
Traceback (most recent call last):
  File "<console>", line 1, in <module>
AttributeError: 'User' object has no attribute 'designation'
>>> Profile.objects.get(user=2).designation
''
>>> Profile.designation = "Dev"
>>> u.profile.designation = "Dev"
>>> u.save()
>>> Profile.objects.get(user=2).designation
'Dev'
>>> Profile.objects.get(user=2).user.username
''
>>> u.profile.username = "Pran"
>>> Profile.objects.get(user=2).user.username
''
>>> u.save()
>>> Profile.objects.get(user=2).user.username
''
>>> u.username = "Pran"
>>> u.save()
>>> Profile.objects.get(user=2).user.username
'Pran'
>>> c = User(first_name="ram")
>>> c.save
<bound method AbstractBaseUser.save of <User: >>
>>> c = User(first_name="ram")
>>> c.save()
>>> Profile.objects.get(user=3)
<Profile: ram >
>>> 

